Workbook
Name lst_FiltroCategoria: Configuración!$K$6:$K$11
Name lst_FiltroRegion: Configuración!$M$6:$M$11
Name lst_FiltroSucursal: Configuración!$O$6:$O$16
Name lst_MesAb: Configuración!$I$6:$I$17
Name lst_Meses: Configuración!$H$6:$H$17

Sheet Dashboard
B2: RETAIL ANDINA S.A. · TABLERO EJECUTIVO DE VENTAS Y RENTABILIDAD
B3: Pre-entrega Módulo 9 | Período analizado: 2026 | Dataset simulado
B4: FILTROS | C4: CATEGORÍA | F4: REGIÓN | I4: SUCURSAL
C5: Todas | F5: Todas | I5: Todas | M5: =Cálculos!$C$110
B7: VENTAS YTD | E7: MARGEN BRUTO YTD | H7: MARGEN % | K7: CUMPLIMIENTO OBJETIVO | N7: TICKET PROMEDIO | Q7: PROYECCIÓN DE CIERRE
B8: =Cálculos!$C$12 -> 3.0973802e+08 | E8: =Cálculos!$C$15 -> 86527609 | H8: =Cálculos!$C$17 -> 0.27935741 | K8: =Cálculos!$C$22 -> 0.97679264 | N8: =Cálculos!$C$25 -> 443115.9 | Q8: =Cálculos!$C$26 -> 6.7484046e+08
B9: =Cálculos!$C$14 -> 0.11107743 | E9: =Cálculos!$C$20 -> 0.020745437 | H9: =Cálculos!$C$19 -> -2.4722042 | K9: =Cálculos!$C$22-1 -> -0.023207357 | N9: =Cálculos!$C$123 -> 0.11425648 | Q9: =Cálculos!$C$28-1 -> -0.03538824
B10: vs. mismo período año anterior | E10: variación del margen en $ | H10: vs. mismo período año anterior | K10: desvío contra el objetivo YTD | N10: vs. mismo período año anterior | Q10: vs. objetivo anual
B12: EVOLUCIÓN Y COMPOSICIÓN DEL RESULTADO
B13: =Cálculos!$C$104 -> Las ventas crecen, pero el margen cae | L13: =Cálculos!$C$105 -> Tecnología impulsa el crecimiento de ventas
B14: Ventas mensuales (columnas, eje izquierdo) y margen % (línea, eje derecho) · últimos 18 meses | L14: Ventas YTD por categoría: año en curso vs. mismo período del año anterior
B32: =Cálculos!$C$106 -> Tecnología es la categoría que más margen pierde | L32: =Cálculos!$C$107 -> Patagonia es la región más lejos del objetivo
B33: Margen % por categoría: año en curso vs. mismo período del año anterior · en puntos porcentuales | L33: Ventas reales vs. objetivo YTD por región
B51: PROYECCIÓN DE CIERRE Y RANKING OPERATIVO
B52: =Cálculos!$C$108 -> El año cerraría cerca del 96% del objetivo | M52: Ranking de sucursales por ventas YTD
B53: Ventas reales acumuladas + proyección de los meses pendientes, contra el objetivo mensual | M53: Ordenado de mayor a menor · margen % y cumplimiento de objetivo
M54: # | N54: Sucursal | Q54: Ventas YTD | R54: Margen % | S54: Cumpl. %
M55: 1 | N55: =INDEX(Cálculos!$B$72:$B$81,MATCH(LARGE(Cálculos!$G$72:$G$81,1),Cálculos!$G$72:$G$81,0)) -> Sucursal Palermo | Q55: =INDEX(Cálculos!$D$72:$D$81,MATCH(LARGE(Cálculos!$G$72:$G$81,1),Cálculos!$G$72:$G$81,0)) -> 62409453 | R55: =INDEX(Cálculos!$E$72:$E$81,MATCH(LARGE(Cálculos!$G$72:$G$81,1),Cálculos!$G$72:$G$81,0)) -> 0.26782357 | S55: =INDEX(Cálculos!$F$72:$F$81,MATCH(LARGE(Cálculos!$G$72:$G$81,1),Cálculos!$G$72:$G$81,0)) -> 1.0311351
M56: 2 | N56: =INDEX(Cálculos!$B$72:$B$81,MATCH(LARGE(Cálculos!$G$72:$G$81,2),Cálculos!$G$72:$G$81,0)) -> Sucursal Avellaneda | Q56: =INDEX(Cálculos!$D$72:$D$81,MATCH(LARGE(Cálculos!$G$72:$G$81,2),Cálculos!$G$72:$G$81,0)) -> 50411577 | R56: =INDEX(Cálculos!$E$72:$E$81,MATCH(LARGE(Cálculos!$G$72:$G$81,2),Cálculos!$G$72:$G$81,0)) -> 0.26304125 | S56: =INDEX(Cálculos!$F$72:$F$81,MATCH(LARGE(Cálculos!$G$72:$G$81,2),Cálculos!$G$72:$G$81,0)) -> 1.0157685
M57: 3 | N57: =INDEX(Cálculos!$B$72:$B$81,MATCH(LARGE(Cálculos!$G$72:$G$81,3),Cálculos!$G$72:$G$81,0)) -> Sucursal Córdoba Centro | Q57: =INDEX(Cálculos!$D$72:$D$81,MATCH(LARGE(Cálculos!$G$72:$G$81,3),Cálculos!$G$72:$G$81,0)) -> 42066082 | R57: =INDEX(Cálculos!$E$72:$E$81,MATCH(LARGE(Cálculos!$G$72:$G$81,3),Cálculos!$G$72:$G$81,0)) -> 0.32152401 | S57: =INDEX(Cálculos!$F$72:$F$81,MATCH(LARGE(Cálculos!$G$72:$G$81,3),Cálculos!$G$72:$G$81,0)) -> 0.99247568
M58: 4 | N58: =INDEX(Cálculos!$B$72:$B$81,MATCH(LARGE(Cálculos!$G$72:$G$81,4),Cálculos!$G$72:$G$81,0)) -> Sucursal Rosario | Q58: =INDEX(Cálculos!$D$72:$D$81,MATCH(LARGE(Cálculos!$G$72:$G$81,4),Cálculos!$G$72:$G$81,0)) -> 34866519 | R58: =INDEX(Cálculos!$E$72:$E$81,MATCH(LARGE(Cálculos!$G$72:$G$81,4),Cálculos!$G$72:$G$81,0)) -> 0.28300208 | S58: =INDEX(Cálculos!$F$72:$F$81,MATCH(LARGE(Cálculos!$G$72:$G$81,4),Cálculos!$G$72:$G$81,0)) -> 0.9737891
M59: 5 | N59: =INDEX(Cálculos!$B$72:$B$81,MATCH(LARGE(Cálculos!$G$72:$G$81,5),Cálculos!$G$72:$G$81,0)) -> Sucursal Río Cuarto | Q59: =INDEX(Cálculos!$D$72:$D$81,MATCH(LARGE(Cálculos!$G$72:$G$81,5),Cálculos!$G$72:$G$81,0)) -> 27949677 | R59: =INDEX(Cálculos!$E$72:$E$81,MATCH(LARGE(Cálculos!$G$72:$G$81,5),Cálculos!$G$72:$G$81,0)) -> 0.29954712 | S59: =INDEX(Cálculos!$F$72:$F$81,MATCH(LARGE(Cálculos!$G$72:$G$81,5),Cálculos!$G$72:$G$81,0)) -> 0.99179154
M60: 6 | N60: =INDEX(Cálculos!$B$72:$B$81,MATCH(LARGE(Cálculos!$G$72:$G$81,6),Cálculos!$G$72:$G$81,0)) -> Sucursal Mendoza | Q60: =INDEX(Cálculos!$D$72:$D$81,MATCH(LARGE(Cálculos!$G$72:$G$81,6),Cálculos!$G$72:$G$81,0)) -> 25829035 | R60: =INDEX(Cálculos!$E$72:$E$81,MATCH(LARGE(Cálculos!$G$72:$G$81,6),Cálculos!$G$72:$G$81,0)) -> 0.29064212 | S60: =INDEX(Cálculos!$F$72:$F$81,MATCH(LARGE(Cálculos!$G$72:$G$81,6),Cálculos!$G$72:$G$81,0)) -> 0.98168198
M61: 7 | N61: =INDEX(Cálculos!$B$72:$B$81,MATCH(LARGE(Cálculos!$G$72:$G$81,7),Cálculos!$G$72:$G$81,0)) -> Sucursal Paraná | Q61: =INDEX(Cálculos!$D$72:$D$81,MATCH(LARGE(Cálculos!$G$72:$G$81,7),Cálculos!$G$72:$G$81,0)) -> 21507788 | R61: =INDEX(Cálculos!$E$72:$E$81,MATCH(LARGE(Cálculos!$G$72:$G$81,7),Cálculos!$G$72:$G$81,0)) -> 0.27655168 | S61: =INDEX(Cálculos!$F$72:$F$81,MATCH(LARGE(Cálculos!$G$72:$G$81,7),Cálculos!$G$72:$G$81,0)) -> 0.97713818
M62: 8 | N62: =INDEX(Cálculos!$B$72:$B$81,MATCH(LARGE(Cálculos!$G$72:$G$81,8),Cálculos!$G$72:$G$81,0)) -> Sucursal Neuquén | Q62: =INDEX(Cálculos!$D$72:$D$81,MATCH(LARGE(Cálculos!$G$72:$G$81,8),Cálculos!$G$72:$G$81,0)) -> 17918836 | R62: =INDEX(Cálculos!$E$72:$E$81,MATCH(LARGE(Cálculos!$G$72:$G$81,8),Cálculos!$G$72:$G$81,0)) -> 0.24456258 | S62: =INDEX(Cálculos!$F$72:$F$81,MATCH(LARGE(Cálculos!$G$72:$G$81,8),Cálculos!$G$72:$G$81,0)) -> 0.81176207
M63: 9 | N63: =INDEX(Cálculos!$B$72:$B$81,MATCH(LARGE(Cálculos!$G$72:$G$81,9),Cálculos!$G$72:$G$81,0)) -> Sucursal San Juan | Q63: =INDEX(Cálculos!$D$72:$D$81,MATCH(LARGE(Cálculos!$G$72:$G$81,9),Cálculos!$G$72:$G$81,0)) -> 13912891 | R63: =INDEX(Cálculos!$E$72:$E$81,MATCH(LARGE(Cálculos!$G$72:$G$81,9),Cálculos!$G$72:$G$81,0)) -> 0.28103457 | S63: =INDEX(Cálculos!$F$72:$F$81,MATCH(LARGE(Cálculos!$G$72:$G$81,9),Cálculos!$G$72:$G$81,0)) -> 0.98792096
M64: 10 | N64: =INDEX(Cálculos!$B$72:$B$81,MATCH(LARGE(Cálculos!$G$72:$G$81,10),Cálculos!$G$72:$G$81,0)) -> Sucursal Bariloche | Q64: =INDEX(Cálculos!$D$72:$D$81,MATCH(LARGE(Cálculos!$G$72:$G$81,10),Cálculos!$G$72:$G$81,0)) -> 12866159 | R64: =INDEX(Cálculos!$E$72:$E$81,MATCH(LARGE(Cálculos!$G$72:$G$81,10),Cálculos!$G$72:$G$81,0)) -> 0.23631486 | S64: =INDEX(Cálculos!$F$72:$F$81,MATCH(LARGE(Cálculos!$G$72:$G$81,10),Cálculos!$G$72:$G$81,0)) -> 0.7994879
B70: • Fuente: hoja Datos (dataset sintético, 2.088 operaciones entre enero 2025 y junio 2026). Empresa ficticia con fines académicos.
B71: • YTD = acumulado de enero al último mes cerrado del año en curso. Todas las comparaciones usan el mismo corte del año anterior.
B72: • Proyección = promedio de los últimos 3 meses cerrados × índice de estacionalidad del mismo mes del año anterior. No incorpora decisiones comerciales futuras.
B73: • Los tres filtros afectan simultáneamente a KPIs, gráficos y ranking. Si se combina una sucursal con una región a la que no pertenece, el tablero avisa que no hay datos.
B74: • Ejes truncados y declarados: margen % del gráfico de evolución entre 20% y 35%, cumplimiento por región entre 60% y 120%, para hacer visible la variación.

Sheet Datos
A1: Fecha | B1: Año | C1: Mes | D1: Nombre_Mes | E1: Trimestre | F1: ID_Venta | G1: Producto | H1: Categoría | I1: Subcategoría | J1: Región | K1: Sucursal | L1: Vendedor | M1: Unidades | N1: Precio_Unitario | O1: Facturación | P1: Costo_Unitario | Q1: Costo_Total | R1: Margen_Bruto | S1: Margen_%
A2: 45658 | B2: =YEAR($A2) -> 2025 | C2: =MONTH($A2) -> 1 | D2: =INDEX(lst_Meses,MONTH($A2)) -> Enero | E2: ="T"&ROUNDUP(MONTH($A2)/3,0) -> T1 | F2: V-100013 | G2: Auriculares Bluetooth | H2: Tecnología | I2: Audio y Video | J2: Litoral | K2: Sucursal Paraná | L2: A. Molina | M2: 5 | N2: 65111.73 | O2: =$M2*$N2 -> 325558.65 | P2: 45023.42 | Q2: =$M2*$P2 -> 225117.1 | R2: =$O2-$Q2 -> 100441.55 | S2: =IFERROR($R2/$O2,0) -> 0.3085206
A3: 45658 | B3: =YEAR($A3) -> 2025 | C3: =MONTH($A3) -> 1 | D3: =INDEX(lst_Meses,MONTH($A3)) -> Enero | E3: ="T"&ROUNDUP(MONTH($A3)/3,0) -> T1 | F3: V-100025 | G3: Vino Malbec 750ml | H3: Alimentos | I3: Bebidas | J3: AMBA | K3: Sucursal Palermo | L3: J. Benítez | M3: 116 | N3: 5794.08 | O3: =$M3*$N3 -> 672113.28 | P3: 4799.82 | Q3: =$M3*$P3 -> 556779.12 | R3: =$O3-$Q3 -> 115334.16 | S3: =IFERROR($R3/$O3,0) -> 0.17159929
A4: 45658 | B4: =YEAR($A4) -> 2025 | C4: =MONTH($A4) -> 1 | D4: =INDEX(lst_Meses,MONTH($A4)) -> Enero | E4: ="T"&ROUNDUP(MONTH($A4)/3,0) -> T1 | F4: V-100046 | G4: Aceite de Girasol 1,5L | H4: Alimentos | I4: Almacén | J4: Patagonia | K4: Sucursal Bariloche | L4: O. Uriarte | M4: 91 | N4: 3028.48 | O4: =$M4*$N4 -> 275591.68 | P4: 2601.9 | Q4: =$M4*$P4 -> 236772.9 | R4: =$O4-$Q4 -> 38818.78 | S4: =IFERROR($R4/$O4,0) -> 0.14085614
A5: 45658 | B5: =YEAR($A5) -> 2025 | C5: =MONTH($A5) -> 1 | D5: =INDEX(lst_Meses,MONTH($A5)) -> Enero | E5: ="T"&ROUNDUP(MONTH($A5)/3,0) -> T1 | F5: V-100055 | G5: Juego de Sábanas Queen | H5: Hogar | I5: Textil Hogar | J5: Centro | K5: Sucursal Río Cuarto | L5: C. Ibarra | M5: 9 | N5: 43517.06 | O5: =$M5*$N5 -> 391653.54 | P5: 28603.01 | Q5: =$M5*$P5 -> 257427.09 | R5: =$O5-$Q5 -> 134226.45 | S5: =IFERROR($R5/$O5,0) -> 0.34271732
A6: 45658 | B6: =YEAR($A6) -> 2025 | C6: =MONTH($A6) -> 1 | D6: =INDEX(lst_Meses,MONTH($A6)) -> Enero | E6: ="T"&ROUNDUP(MONTH($A6)/3,0) -> T1 | F6: V-100057 | G6: Juego de Sábanas Queen | H6: Hogar | I6: Textil Hogar | J6: Litoral | K6: Sucursal Rosario | L6: D. Ledesma | M6: 2 | N6: 37712.61 | O6: =$M6*$N6 -> 75425.22 | P6: 25852.3 | Q6: =$M6*$P6 -> 51704.6 | R6: =$O6-$Q6 -> 23720.62 | S6: =IFERROR($R6/$O6,0) -> 0.31449189
A7: 45658 | B7: =YEAR($A7) -> 2025 | C7: =MONTH($A7) -> 1 | D7: =INDEX(lst_Meses,MONTH($A7)) -> Enero | E7: ="T"&ROUNDUP(MONTH($A7)/3,0) -> T1 | F7: V-100067 | G7: Juego de Sábanas Queen | H7: Hogar | I7: Textil Hogar | J7: Patagonia | K7: Sucursal Neuquén | L7: H. Sosa | M7: 1 | N7: 9323.22 | O7: =$M7*$N7 -> 9323.22 | P7: 6615.4 | Q7: =$M7*$P7 -> 6615.4 | R7: =$O7-$Q7 -> 2707.82 | S7: =IFERROR($R7/$O7,0) -> 0.29043828
A8: 45658 | B8: =YEAR($A8) -> 2025 | C8: =MONTH($A8) -> 1 | D8: =INDEX(lst_Meses,MONTH($A8)) -> Enero | E8: ="T"&ROUNDUP(MONTH($A8)/3,0) -> T1 | F8: V-100091 | G8: Calzado Urbano | H8: Indumentaria | I8: Calzado | J8: Patagonia | K8: Sucursal Bariloche | L8: K. Vera | M8: 2 | N8: 56892.63 | O8: =$M8*$N8 -> 113785.26 | P8: 33812.62 | Q8: =$M8*$P8 -> 67625.24 | R8: =$O8-$Q8 -> 46160.02 | S8: =IFERROR($R8/$O8,0) -> 0.40567662
A9: 45658 | B9: =YEAR($A9) -> 2025 | C9: =MONTH($A9) -> 1 | D9: =INDEX(lst_Meses,MONTH($A9)) -> Enero | E9: ="T"&ROUNDUP(MONTH($A9)/3,0) -> T1 | F9: V-100094 | G9: Pelota de Fútbol Nº5 | H9: Deportes | I9: Accesorios | J9: AMBA | K9: Sucursal Palermo | L9: J. Benítez | M9: 10 | N9: 20030.93 | O9: =$M9*$N9 -> 200309.3 | P9: 11969.46 | Q9: =$M9*$P9 -> 119694.6 | R9: =$O9-$Q9 -> 80614.7 | S9: =IFERROR($R9/$O9,0) -> 0.40245111
A10: 45658 | B10: =YEAR($A10) -> 2025 | C10: =MONTH($A10) -> 1 | D10: =INDEX(lst_Meses,MONTH($A10)) -> Enero | E10: ="T"&ROUNDUP(MONTH($A10)/3,0) -> T1 | F10: V-100097 | G10: Pelota de Fútbol Nº5 | H10: Deportes | I10: Accesorios | J10: AMBA | K10: Sucursal Avellaneda | L10: L. Correa | M10: 9 | N10: 20316.46 | O10: =$M10*$N10 -> 182848.14 | P10: 12450.73 | Q10: =$M10*$P10 -> 112056.57 | R10: =$O10-$Q10 -> 70791.57 | S10: =IFERROR($R10/$O10,0) -> 0.38716046
A11: 45659 | B11: =YEAR($A11) -> 2025 | C11: =MONTH($A11) -> 1 | D11: =INDEX(lst_Meses,MONTH($A11)) -> Enero | E11: ="T"&ROUNDUP(MONTH($A11)/3,0) -> T1 | F11: V-100070 | G11: Juego de Sábanas Queen | H11: Hogar | I11: Textil Hogar | J11: Patagonia | K11: Sucursal Bariloche | L11: K. Vera | M11: 5 | N11: 43110.58 | O11: =$M11*$N11 -> 215552.9 | P11: 30715.75 | Q11: =$M11*$P11 -> 153578.75 | R11: =$O11-$Q11 -> 61974.15 | S11: =IFERROR($R11/$O11,0) -> 0.28751249
A12: 45659 | B12: =YEAR($A12) -> 2025 | C12: =MONTH($A12) -> 1 | D12: =INDEX(lst_Meses,MONTH($A12)) -> Enero | E12: ="T"&ROUNDUP(MONTH($A12)/3,0) -> T1 | F12: V-100078 | G12: Jean Clásico | H12: Indumentaria | I12: Pantalones | J12: Centro | K12: Sucursal Río Cuarto | L12: C. Ibarra | M12: 5 | N12: 41761.92 | O12: =$M12*$N12 -> 208809.6 | P12: 21831 | Q12: =$M12*$P12 -> 109155 | R12: =$O12-$Q12 -> 99654.6 | S12: =IFERROR($R12/$O12,0) -> 0.47725105
A13: 45660 | B13: =YEAR($A13) -> 2025 | C13: =MONTH($A13) -> 1 | D13: =INDEX(lst_Meses,MONTH($A13)) -> Enero | E13: ="T"&ROUNDUP(MONTH($A13)/3,0) -> T1 | F13: V-100028 | G13: Vino Malbec 750ml | H13: Alimentos | I13: Bebidas | J13: AMBA | K13: Sucursal Avellaneda | L13: P. Domínguez | M13: 133 | N13: 5730.73 | O13: =$M13*$N13 -> 762187.09 | P13: 4785.82 | Q13: =$M13*$P13 -> 636514.06 | R13: =$O13-$Q13 -> 125673.03 | S13: =IFERROR($R13/$O13,0) -> 0.16488475
... A2089: 46201 | B2089: =YEAR($A2089) -> 2026 | C2089: =MONTH($A2089) -> 6 | D2089: =INDEX(lst_Meses,MONTH($A2089)) -> Junio | E2089: ="T"&ROUNDUP(MONTH($A2089)/3,0) -> T2 | F2089: V-102061 | G2089: Campera Puffer | H2089: Indumentaria | I2089: Abrigo | J2089: Patagonia | K2089: Sucursal Neuquén | L2089: H. Sosa | M2089: 2 | N2089: 90101.29 | O2089: =$M2089*$N2089 -> 180202.58 | P2089: 52349.09 | Q2089: =$M2089*$P2089 -> 104698.18 | R2089: =$O2089-$Q2089 -> 75504.4 | S2089: =IFERROR($R2089/$O2089,0) -> 0.41899733

Sheet Cálculos
B2: 1 · PARÁMETROS DERIVADOS Y FILTROS ACTIVOS
B3: Año en curso (máximo del dataset) | C3: =MAX(Datos!$B$2:$B$2089) -> 2026
B4: Año anterior (comparativo) | C4: =$C$3-1 -> 2025
B5: N — último mes cerrado del año en curso | C5: =SUMPRODUCT(MAX((Datos!$B$2:$B$2089=$C$3)*Datos!$C$2:$C$2089)) -> 6
B6: Nombre del mes de cierre | C6: =INDEX(lst_Meses,$C$5) -> Junio
B7: Filtro Categoría | C7: =Dashboard!$C$5 -> Todas | D7: criterio SUMIFS → | E7: =IF($C$7="Todas","*",$C$7) -> *
B8: Filtro Región | C8: =Dashboard!$F$5 -> Todas | D8: criterio SUMIFS → | E8: =IF($C$8="Todas","*",$C$8) -> *
B9: Filtro Sucursal | C9: =Dashboard!$I$5 -> Todas | D9: criterio SUMIFS → | E9: =IF($C$9="Todas","*",$C$9) -> *
B11: 2 · KPIs DEL PERÍODO (YTD = enero al mes N)
B12: Ventas YTD — año en curso ($) | C12: =SUMIFS(Datos!$O$2:$O$2089,Datos!$B$2:$B$2089,$C$3,Datos!$C$2:$C$2089,"<="&$C$5,Datos!$H$2:$H$2089,$E$7,Datos!$J$2:$J$2089,$E$8,Datos!$K$2:$K$2089,$E$9) -> 3.0973802e+08
B13: Ventas YTD — año anterior ($) | C13: =SUMIFS(Datos!$O$2:$O$2089,Datos!$B$2:$B$2089,$C$4,Datos!$C$2:$C$2089,"<="&$C$5,Datos!$H$2:$H$2089,$E$7,Datos!$J$2:$J$2089,$E$8,Datos!$K$2:$K$2089,$E$9) -> 2.7877267e+08
B14: Variación de ventas YTD (%) | C14: =IFERROR($C$12/$C$13-1,0) -> 0.11107743
B15: Margen bruto YTD — año en curso ($) | C15: =SUMIFS(Datos!$R$2:$R$2089,Datos!$B$2:$B$2089,$C$3,Datos!$C$2:$C$2089,"<="&$C$5,Datos!$H$2:$H$2089,$E$7,Datos!$J$2:$J$2089,$E$8,Datos!$K$2:$K$2089,$E$9) -> 86527609
B16: Margen bruto YTD — año anterior ($) | C16: =SUMIFS(Datos!$R$2:$R$2089,Datos!$B$2:$B$2089,$C$4,Datos!$C$2:$C$2089,"<="&$C$5,Datos!$H$2:$H$2089,$E$7,Datos!$J$2:$J$2089,$E$8,Datos!$K$2:$K$2089,$E$9) -> 84769039
B17: Margen % YTD — año en curso | C17: =IFERROR($C$15/$C$12,0) -> 0.27935741
B18: Margen % YTD — año anterior | C18: =IFERROR($C$16/$C$13,0) -> 0.30407945
B19: Variación de margen (p.p.) | C19: =($C$17-$C$18)*100 -> -2.4722042
B20: Variación de margen bruto $ (%) | C20: =IFERROR($C$15/$C$16-1,0) -> 0.020745437
B21: Objetivo YTD ($) | C21: =SUMIFS(Configuración!$G$21:$G$1220,Configuración!$B$21:$B$1220,$C$3,Configuración!$C$21:$C$1220,"<="&$C$5,Configuración!$F$21:$F$1220,$E$7,Configuración!$D$21:$D$1220,$E$8,Configuración!$E$21:$E$1220,$E$9) -> 317097000
B22: Cumplimiento de objetivo YTD (%) | C22: =IFERROR($C$12/$C$21,0) -> 0.97679264
B23: Unidades YTD | C23: =SUMIFS(Datos!$M$2:$M$2089,Datos!$B$2:$B$2089,$C$3,Datos!$C$2:$C$2089,"<="&$C$5,Datos!$H$2:$H$2089,$E$7,Datos!$J$2:$J$2089,$E$8,Datos!$K$2:$K$2089,$E$9) -> 26906
B24: Operaciones YTD (nº de ventas) | C24: =COUNTIFS(Datos!$B$2:$B$2089,$C$3,Datos!$C$2:$C$2089,"<="&$C$5,Datos!$H$2:$H$2089,$E$7,Datos!$J$2:$J$2089,$E$8,Datos!$K$2:$K$2089,$E$9) -> 699
B25: Ticket promedio YTD ($) | C25: =IFERROR($C$12/$C$24,0) -> 443115.9
B26: Proyección de cierre del año en curso ($) | C26: =SUM($D$85:$D$96)+SUM($E$85:$E$96) -> 6.7484046e+08
B27: Objetivo anual del año en curso ($) | C27: =SUMIFS(Configuración!$G$21:$G$1220,Configuración!$B$21:$B$1220,$C$3,Configuración!$C$21:$C$1220,">0",Configuración!$F$21:$F$1220,$E$7,Configuración!$D$21:$D$1220,$E$8,Configuración!$E$21:$E$1220,$E$9) -> 699598000
B28: Cumplimiento proyectado anual (%) | C28: =IFERROR($C$26/$C$27,0) -> 0.96461176
B30: 3 · EVOLUCIÓN MENSUAL — 18 MESES (alimenta el gráfico 1)
B31: Año | C31: Mes | D31: Período | E31: Ventas ($) | F31: Margen bruto ($) | G31: Margen % | H31: Objetivo ($) | I31: Cumplimiento %
B32: 2025 | C32: 1 | D32: =INDEX(lst_MesAb,$C32)&"-"&RIGHT($B32&"",2) -> ene-25 | E32: =SUMIFS(Datos!$O$2:$O$2089,Datos!$B$2:$B$2089,$B32,Datos!$C$2:$C$2089,$C32,Datos!$H$2:$H$2089,$E$7,Datos!$J$2:$J$2089,$E$8,Datos!$K$2:$K$2089,$E$9) -> 40141723 | F32: =SUMIFS(Datos!$R$2:$R$2089,Datos!$B$2:$B$2089,$B32,Datos!$C$2:$C$2089,$C32,Datos!$H$2:$H$2089,$E$7,Datos!$J$2:$J$2089,$E$8,Datos!$K$2:$K$2089,$E$9) -> 12424104 | G32: =IFERROR($F32/$E32,0) -> 0.309506 | H32: =SUMIFS(Configuración!$G$21:$G$1220,Configuración!$B$21:$B$1220,$B32,Configuración!$C$21:$C$1220,$C32,Configuración!$F$21:$F$1220,$E$7,Configuración!$D$21:$D$1220,$E$8,Configuración!$E$21:$E$1220,$E$9) -> 40668000 | I32: =IFERROR($E32/$H32,0) -> 0.98705918
B33: 2025 | C33: 2 | D33: =INDEX(lst_MesAb,$C33)&"-"&RIGHT($B33&"",2) -> feb-25 | E33: =SUMIFS(Datos!$O$2:$O$2089,Datos!$B$2:$B$2089,$B33,Datos!$C$2:$C$2089,$C33,Datos!$H$2:$H$2089,$E$7,Datos!$J$2:$J$2089,$E$8,Datos!$K$2:$K$2089,$E$9) -> 38958355 | F33: =SUMIFS(Datos!$R$2:$R$2089,Datos!$B$2:$B$2089,$B33,Datos!$C$2:$C$2089,$C33,Datos!$H$2:$H$2089,$E$7,Datos!$J$2:$J$2089,$E$8,Datos!$K$2:$K$2089,$E$9) -> 11908749 | G33: =IFERROR($F33/$E33,0) -> 0.30567895 | H33: =SUMIFS(Configuración!$G$21:$G$1220,Configuración!$B$21:$B$1220,$B33,Configuración!$C$21:$C$1220,$C33,Configuración!$F$21:$F$1220,$E$7,Configuración!$D$21:$D$1220,$E$8,Configuración!$E$21:$E$1220,$E$9) -> 39114000 | I33: =IFERROR($E33/$H33,0) -> 0.99602074
B34: 2025 | C34: 3 | D34: =INDEX(lst_MesAb,$C34)&"-"&RIGHT($B34&"",2) -> mar-25 | E34: =SUMIFS(Datos!$O$2:$O$2089,Datos!$B$2:$B$2089,$B34,Datos!$C$2:$C$2089,$C34,Datos!$H$2:$H$2089,$E$7,Datos!$J$2:$J$2089,$E$8,Datos!$K$2:$K$2089,$E$9) -> 46545185 | F34: =SUMIFS(Datos!$R$2:$R$2089,Datos!$B$2:$B$2089,$B34,Datos!$C$2:$C$2089,$C34,Datos!$H$2:$H$2089,$E$7,Datos!$J$2:$J$2089,$E$8,Datos!$K$2:$K$2089,$E$9) -> 14106191 | G34: =IFERROR($F34/$E34,0) -> 0.30306446 | H34: =SUMIFS(Configuración!$G$21:$G$1220,Configuración!$B$21:$B$1220,$B34,Configuración!$C$21:$C$1220,$C34,Configuración!$F$21:$F$1220,$E$7,Configuración!$D$21:$D$1220,$E$8,Configuración!$E$21:$E$1220,$E$9) -> 46596000 | I34: =IFERROR($E34/$H34,0) -> 0.99890946
B35: 2025 | C35: 4 | D35: =INDEX(lst_MesAb,$C35)&"-"&RIGHT($B35&"",2) -> abr-25 | E35: =SUMIFS(Datos!$O$2:$O$2089,Datos!$B$2:$B$2089,$B35,Datos!$C$2:$C$2089,$C35,Datos!$H$2:$H$2089,$E$7,Datos!$J$2:$J$2089,$E$8,Datos!$K$2:$K$2089,$E$9) -> 45970047 | F35: =SUMIFS(Datos!$R$2:$R$2089,Datos!$B$2:$B$2089,$B35,Datos!$C$2:$C$2089,$C35,Datos!$H$2:$H$2089,$E$7,Datos!$J$2:$J$2089,$E$8,Datos!$K$2:$K$2089,$E$9) -> 13811250 | G35: =IFERROR($F35/$E35,0) -> 0.3004402 | H35: =SUMIFS(Configuración!$G$21:$G$1220,Configuración!$B$21:$B$1220,$B35,Configuración!$C$21:$C$1220,$C35,Configuración!$F$21:$F$1220,$E$7,Configuración!$D$21:$D$1220,$E$8,Configuración!$E$21:$E$1220,$E$9) -> 45448000 | I35: =IFERROR($E35/$H35,0) -> 1.0114867
B36: 2025 | C36: 5 | D36: =INDEX(lst_MesAb,$C36)&"-"&RIGHT($B36&"",2) -> may-25 | E36: =SUMIFS(Datos!$O$2:$O$2089,Datos!$B$2:$B$2089,$B36,Datos!$C$2:$C$2089,$C36,Datos!$H$2:$H$2089,$E$7,Datos!$J$2:$J$2089,$E$8,Datos!$K$2:$K$2089,$E$9) -> 50093019 | F36: =SUMIFS(Datos!$R$2:$R$2089,Datos!$B$2:$B$2089,$B36,Datos!$C$2:$C$2089,$C36,Datos!$H$2:$H$2089,$E$7,Datos!$J$2:$J$2089,$E$8,Datos!$K$2:$K$2089,$E$9) -> 15240600 | G36: =IFERROR($F36/$E36,0) -> 0.30424598 | H36: =SUMIFS(Configuración!$G$21:$G$1220,Configuración!$B$21:$B$1220,$B36,Configuración!$C$21:$C$1220,$C36,Configuración!$F$21:$F$1220,$E$7,Configuración!$D$21:$D$1220,$E$8,Configuración!$E$21:$E$1220,$E$9) -> 51315000 | I36: =IFERROR($E36/$H36,0) -> 0.97618667
B37: 2025 | C37: 6 | D37: =INDEX(lst_MesAb,$C37)&"-"&RIGHT($B37&"",2) -> jun-25 | E37: =SUMIFS(Datos!$O$2:$O$2089,Datos!$B$2:$B$2089,$B37,Datos!$C$2:$C$2089,$C37,Datos!$H$2:$H$2089,$E$7,Datos!$J$2:$J$2089,$E$8,Datos!$K$2:$K$2089,$E$9) -> 57064337 | F37: =SUMIFS(Datos!$R$2:$R$2089,Datos!$B$2:$B$2089,$B37,Datos!$C$2:$C$2089,$C37,Datos!$H$2:$H$2089,$E$7,Datos!$J$2:$J$2089,$E$8,Datos!$K$2:$K$2089,$E$9) -> 17278145 | G37: =IFERROR($F37/$E37,0) -> 0.30278359 | H37: =SUMIFS(Configuración!$G$21:$G$1220,Configuración!$B$21:$B$1220,$B37,Configuración!$C$21:$C$1220,$C37,Configuración!$F$21:$F$1220,$E$7,Configuración!$D$21:$D$1220,$E$8,Configuración!$E$21:$E$1220,$E$9) -> 55488000 | I37: =IFERROR($E37/$H37,0) -> 1.0284086
B38: 2025 | C38: 7 | D38: =INDEX(lst_MesAb,$C38)&"-"&RIGHT($B38&"",2) -> jul-25 | E38: =SUMIFS(Datos!$O$2:$O$2089,Datos!$B$2:$B$2089,$B38,Datos!$C$2:$C$2089,$C38,Datos!$H$2:$H$2089,$E$7,Datos!$J$2:$J$2089,$E$8,Datos!$K$2:$K$2089,$E$9) -> 55403382 | F38: =SUMIFS(Datos!$R$2:$R$2089,Datos!$B$2:$B$2089,$B38,Datos!$C$2:$C$2089,$C38,Datos!$H$2:$H$2089,$E$7,Datos!$J$2:$J$2089,$E$8,Datos!$K$2:$K$2089,$E$9) -> 16709708 | G38: =IFERROR($F38/$E38,0) -> 0.30160087 | H38: =SUMIFS(Configuración!$G$21:$G$1220,Configuración!$B$21:$B$1220,$B38,Configuración!$C$21:$C$1220,$C38,Configuración!$F$21:$F$1220,$E$7,Configuración!$D$21:$D$1220,$E$8,Configuración!$E$21:$E$1220,$E$9) -> 55904000 | I38: =IFERROR($E38/$H38,0) -> 0.99104504
B39: 2025 | C39: 8 | D39: =INDEX(lst_MesAb,$C39)&"-"&RIGHT($B39&"",2) -> ago-25 | E39: =SUMIFS(Datos!$O$2:$O$2089,Datos!$B$2:$B$2089,$B39,Datos!$C$2:$C$2089,$C39,Datos!$H$2:$H$2089,$E$7,Datos!$J$2:$J$2089,$E$8,Datos!$K$2:$K$2089,$E$9) -> 47189517 | F39: =SUMIFS(Datos!$R$2:$R$2089,Datos!$B$2:$B$2089,$B39,Datos!$C$2:$C$2089,$C39,Datos!$H$2:$H$2089,$E$7,Datos!$J$2:$J$2089,$E$8,Datos!$K$2:$K$2089,$E$9) -> 13885824 | G39: =IFERROR($F39/$E39,0) -> 0.29425653 | H39: =SUMIFS(Configuración!$G$21:$G$1220,Configuración!$B$21:$B$1220,$B39,Configuración!$C$21:$C$1220,$C39,Configuración!$F$21:$F$1220,$E$7,Configuración!$D$21:$D$1220,$E$8,Configuración!$E$21:$E$1220,$E$9) -> 48442000 | I39: =IFERROR($E39/$H39,0) -> 0.97414468
B40: 2025 | C40: 9 | D40: =INDEX(lst_MesAb,$C40)&"-"&RIGHT($B40&"",2) -> sep-25 | E40: =SUMIFS(Datos!$O$2:$O$2089,Datos!$B$2:$B$2089,$B40,Datos!$C$2:$C$2089,$C40,Datos!$H$2:$H$2089,$E$7,Datos!$J$2:$J$2089,$E$8,Datos!$K$2:$K$2089,$E$9) -> 48017663 | F40: =SUMIFS(Datos!$R$2:$R$2089,Datos!$B$2:$B$2089,$B40,Datos!$C$2:$C$2089,$C40,Datos!$H$2:$H$2089,$E$7,Datos!$J$2:$J$2089,$E$8,Datos!$K$2:$K$2089,$E$9) -> 14077374 | G40: =IFERROR($F40/$E40,0) -> 0.29317073 | H40: =SUMIFS(Configuración!$G$21:$G$1220,Configuración!$B$21:$B$1220,$B40,Configuración!$C$21:$C$1220,$C40,Configuración!$F$21:$F$1220,$E$7,Configuración!$D$21:$D$1220,$E$8,Configuración!$E$21:$E$1220,$E$9) -> 47804000 | I40: =IFERROR($E40/$H40,0) -> 1.0044696
B41: 2025 | C41: 10 | D41: =INDEX(lst_MesAb,$C41)&"-"&RIGHT($B41&"",2) -> oct-25 | E41: =SUMIFS(Datos!$O$2:$O$2089,Datos!$B$2:$B$2089,$B41,Datos!$C$2:$C$2089,$C41,Datos!$H$2:$H$2089,$E$7,Datos!$J$2:$J$2089,$E$8,Datos!$K$2:$K$2089,$E$9) -> 50818732 | F41: =SUMIFS(Datos!$R$2:$R$2089,Datos!$B$2:$B$2089,$B41,Datos!$C$2:$C$2089,$C41,Datos!$H$2:$H$2089,$E$7,Datos!$J$2:$J$2089,$E$8,Datos!$K$2:$K$2089,$E$9) -> 14708618 | G41: =IFERROR($F41/$E41,0) -> 0.289433 | H41: =SUMIFS(Configuración!$G$21:$G$1220,Configuración!$B$21:$B$1220,$B41,Configuración!$C$21:$C$1220,$C41,Configuración!$F$21:$F$1220,$E$7,Configuración!$D$21:$D$1220,$E$8,Configuración!$E$21:$E$1220,$E$9) -> 51547000 | I41: =IFERROR($E41/$H41,0) -> 0.98587178
B42: 2025 | C42: 11 | D42: =INDEX(lst_MesAb,$C42)&"-"&RIGHT($B42&"",2) -> nov-25 | E42: =SUMIFS(Datos!$O$2:$O$2089,Datos!$B$2:$B$2089,$B42,Datos!$C$2:$C$2089,$C42,Datos!$H$2:$H$2089,$E$7,Datos!$J$2:$J$2089,$E$8,Datos!$K$2:$K$2089,$E$9) -> 53634856 | F42: =SUMIFS(Datos!$R$2:$R$2089,Datos!$B$2:$B$2089,$B42,Datos!$C$2:$C$2089,$C42,Datos!$H$2:$H$2089,$E$7,Datos!$J$2:$J$2089,$E$8,Datos!$K$2:$K$2089,$E$9) -> 15497223 | G42: =IFERROR($F42/$E42,0) -> 0.28893939 | H42: =SUMIFS(Configuración!$G$21:$G$1220,Configuración!$B$21:$B$1220,$B42,Configuración!$C$21:$C$1220,$C42,Configuración!$F$21:$F$1220,$E$7,Configuración!$D$21:$D$1220,$E$8,Configuración!$E$21:$E$1220,$E$9) -> 53934000 | I42: =IFERROR($E42/$H42,0) -> 0.99445351
B43: 2025 | C43: 12 | D43: =INDEX(lst_MesAb,$C43)&"-"&RIGHT($B43&"",2) -> dic-25 | E43: =SUMIFS(Datos!$O$2:$O$2089,Datos!$B$2:$B$2089,$B43,Datos!$C$2:$C$2089,$C43,Datos!$H$2:$H$2089,$E$7,Datos!$J$2:$J$2089,$E$8,Datos!$K$2:$K$2089,$E$9) -> 77250516 | F43: =SUMIFS(Datos!$R$2:$R$2089,Datos!$B$2:$B$2089,$B43,Datos!$C$2:$C$2089,$C43,Datos!$H$2:$H$2089,$E$7,Datos!$J$2:$J$2089,$E$8,Datos!$K$2:$K$2089,$E$9) -> 22330669 | G43: =IFERROR($F43/$E43,0) -> 0.28906823 | H43: =SUMIFS(Configuración!$G$21:$G$1220,Configuración!$B$21:$B$1220,$B43,Configuración!$C$21:$C$1220,$C43,Configuración!$F$21:$F$1220,$E$7,Configuración!$D$21:$D$1220,$E$8,Configuración!$E$21:$E$1220,$E$9) -> 76445000 | I43: =IFERROR($E43/$H43,0) -> 1.0105372
...

Sheet Análisis
B2: ANÁLISIS E INTERPRETACIÓN — CONCLUSIONES PROPIAS Y REVISIÓN CON IA
B3: Trabajé en tres etapas: primero miré el dashboard y anoté lo que me llamó la atención, después le pedí a la IA que cuestionara cada conclusión, y por último ajusté el tablero para que lo importante se viera más rápido. Análisis propio → Auditoría con IA → Refinamiento del dashboard
B5: ETAPA A · LO QUE OBSERVÉ EN EL DASHBOARD
B6: Conclusiones propias, escritas después de mirar los gráficos. Van de lo general a lo particular: empresa → categoría → región.
B7: # | C7: Lo que veo | F7: Dónde lo veo en el tablero
B8: 1 | C8: Las ventas de este año vienen bastante mejor que las del año pasado, pero el margen en porcentaje bajó. Estamos vendiendo más, aunque no con la misma rentabilidad. | F8: KPIs de Ventas YTD y Margen %, y el gráfico de evolución: las columnas suben mientras la línea de margen baja.
B9: 2 | C9: Casi todo el crecimiento viene de Tecnología. Lo llamativo es que justo esa categoría es la que más margen perdió contra el año pasado. | F9: Gráfico de ventas por categoría (Tecnología es la barra que más creció) y gráfico de margen % por categoría.
B10: 3 | C10: Patagonia quedó bastante lejos del objetivo y además tiene el margen más bajo del país. Sus dos sucursales aparecen últimas en el ranking. | F10: Gráfico de ventas vs. objetivo por región y tabla de ranking de sucursales.
B13: ETAPA B · LO QUE CUESTIONÓ LA IA
B14: Le pasé cada conclusión y le pedí que buscara los puntos débiles: si la evidencia alcanza, qué más podría explicar el resultado y qué datos me faltan.
B15: # | C15: Mi conclusión | D15: Qué cuestiona la IA | E15: Otra explicación posible | F15: Qué me faltaría saber | G15: Qué haría ahora
B16: 1 | C16: Vendemos más, pero con menos margen. | D16: El margen total es un promedio y puede estar arrastrado por una sola categoría grande. Además son pesos sin ajustar: parte del crecimiento puede ser precio y no volumen. | E16: Que los costos de compra hayan subido más rápido que los precios de venta, o que estemos vendiendo más de las categorías que siempre tuvieron poco margen. | F16: Cómo evolucionaron los costos, qué descuentos se aplicaron y cuánto creció en unidades y no solo en pesos. | G16: Separar cuánto del crecimiento es precio y cuánto es volumen, y mirar el margen categoría por categoría antes de tocar precios.
B17: 2 | C17: Tecnología crece mucho, pero pierde margen. | D17: Que crezca y pierda margen al mismo tiempo no significa que crezca porque bajó el precio. Son dos cosas que pasan juntas, no necesariamente una causa de la otra. | E17: Que dentro de Tecnología se estén vendiendo más productos baratos y menos de los caros, o que haya subido el costo de reposición de los importados. | F17: El detalle por subcategoría y por producto, y el precio de lista contra el precio que realmente se cobró. | G17: Revisar qué productos de Tecnología están creciendo y si son los descuentos o los costos los que están afectando el margen.
B18: 3 | C18: Patagonia está lejos del objetivo. | D18: Antes de decir que el equipo no llegó habría que ver cómo se armó el objetivo. También es la región más chica, así que un desvío en pesos se ve grande en porcentaje. | E18: Un objetivo demasiado alto para el tamaño real de ese mercado, costos de logística más altos que comprimen el margen, o faltantes de stock. | F18: Con qué criterio se fijó el objetivo y cuánto pesa el costo de envío en esa región. | G18: Comparar el objetivo de Patagonia con su venta histórica antes de pedir más volumen, y mirar el margen después de logística.
B21: ETAPA C · QUÉ CAMBIÉ EN EL DASHBOARD DESPUÉS DE ESTE ANÁLISIS
B23: • Acorté los títulos de los gráficos. Antes explicaban todo en una línea larga y le sacaban protagonismo al gráfico; ahora dicen la idea y el número lo pone el gráfico.
B24: • Agregué el KPI de variación de margen en puntos porcentuales, porque mirando solo el margen en pesos la caída no se notaba.
B25: • Sumé el gráfico de margen % por categoría: es donde se ve que el problema está concentrado en Tecnología y no repartido en todas.
B26: • Ordené el ranking de sucursales de mayor a menor y marqué en rojo las que no llegan al objetivo, así no hay que buscarlas.
B27: • Anoté abajo del dashboard que los ejes de porcentaje están truncados, para que la caída no parezca más grande de lo que es.
B29: LÍMITES DE ESTE ANÁLISIS
B31: • Los datos son inventados para este trabajo. Los patrones existen porque fueron generados así, por lo que ninguna conclusión sirve para una empresa real.
B32: • Trabajo con margen bruto (ventas menos costo de mercadería). No están los gastos de estructura, logística ni comerciales, así que no es la rentabilidad final.
B33: • Los valores son nominales, sin ajuste por inflación: parte del crecimiento en pesos puede ser precio. Por eso el tablero también muestra unidades y ticket promedio.
B34: • El año en curso tiene solo 6 meses cerrados, así que todo se compara contra los mismos 6 meses del año anterior.
B35: • La proyección es una extrapolación simple: supone que se repite la estacionalidad del año pasado y que no cambia nada más. Es un escenario, no un pronóstico.
B36: • La IA se usó para revisar conclusiones que ya había escrito, no para generarlas. Las acciones sugeridas todavía habría que validarlas con las áreas involucradas.

Sheet Configuración
B2: CONFIGURACIÓN, PARÁMETROS Y DICCIONARIO DE DATOS
B4: PARÁMETROS GENERALES | H4: LISTAS AUXILIARES
B5: Empresa (ficticia) | C5: Retail Andina S.A. | H5: Mes | I5: Mes abrev. | J5: Categorías | K5: Filtro Categoría | L5: Regiones | M5: Filtro Región | N5: Sucursales | O5: Filtro Sucursal | P5: Región de la sucursal
B6: Rubro | C6: Retail multicanal — 5 categorías, 5 regiones, 10 sucursales | H6: Enero | I6: ene | J6: Tecnología | K6: Todas | L6: AMBA | M6: Todas | N6: Sucursal Palermo | O6: Todas | P6: AMBA
B7: Moneda | C7: Pesos argentinos ($). Valores sin ajuste por inflación. | H7: Febrero | I7: feb | J7: Alimentos | K7: Tecnología | L7: Centro | M7: AMBA | N7: Sucursal Avellaneda | O7: Sucursal Palermo | P7: AMBA
B8: Origen de los datos | C8: Dataset sintético generado para el trabajo académico. No corresponde a una empresa real. | H8: Marzo | I8: mar | J8: Hogar | K8: Alimentos | L8: Litoral | M8: Centro | N8: Sucursal Córdoba Centro | O8: Sucursal Avellaneda | P8: Centro
B9: Período con datos reales | C9: enero 2025 a junio 2026 (18 meses cerrados) | H9: Abril | I9: abr | J9: Indumentaria | K9: Hogar | L9: Cuyo | M9: Litoral | N9: Sucursal Río Cuarto | O9: Sucursal Córdoba Centro | P9: Centro
B10: Año en curso del análisis | C10: Se calcula solo: es el año máximo presente en la hoja Datos. | H10: Mayo | I10: may | J10: Deportes | K10: Indumentaria | L10: Patagonia | M10: Cuyo | N10: Sucursal Rosario | O10: Sucursal Río Cuarto | P10: Litoral
B11: Corte YTD | C11: Enero al último mes con datos del año en curso. Todas las comparaciones usan el mismo corte del año anterior. | H11: Junio | I11: jun | K11: Deportes | M11: Patagonia | N11: Sucursal Paraná | O11: Sucursal Rosario | P11: Litoral
B12: Criterio de proyección | C12: Promedio de ventas de los últimos 3 meses cerrados × índice de estacionalidad del mismo mes del año anterior. | H12: Julio | I12: jul | N12: Sucursal Mendoza | O12: Sucursal Paraná | P12: Cuyo
B13: Definición de objetivos | C13: Objetivo cargado a nivel Año × Mes × Región × Sucursal × Categoría (tabla inferior). Es un input, no un cálculo. | H13: Agosto | I13: ago | N13: Sucursal San Juan | O13: Sucursal Mendoza | P13: Cuyo
B14: Comportamiento de los filtros | C14: Los tres filtros del Dashboard afectan a TODOS los KPIs, gráficos y tablas de forma simultánea. | H14: Septiembre | I14: sep | N14: Sucursal Neuquén | O14: Sucursal San Juan | P14: Patagonia
B15: Margen bruto | C15: Facturación − Costo total. No incluye gastos de estructura, logística ni comerciales. | H15: Octubre | I15: oct | N15: Sucursal Bariloche | O15: Sucursal Neuquén | P15: Patagonia
B16: Celdas editables | C16: Solo las celdas en azul de esta hoja y los desplegables del Dashboard. El resto son fórmulas. | H16: Noviembre | I16: nov | O16: Sucursal Bariloche
H17: Diciembre | I17: dic
B18: OBJETIVOS DE VENTA (input de planificación — celdas azules editables)
B19: Supuesto: el plan comercial se fija por sucursal y categoría. Ejemplo de fila cargada: 2026 | 1 | AMBA | Sucursal Palermo | Tecnología | $ 5.400.000
B20: Año | C20: Mes | D20: Región | E20: Sucursal | F20: Categoría | G20: Objetivo de ventas ($)
B21: 2025 | C21: 1 | D21: AMBA | E21: Sucursal Palermo | F21: Tecnología | G21: 2336000
B22: 2025 | C22: 1 | D22: AMBA | E22: Sucursal Palermo | F22: Alimentos | G22: 1807000
B23: 2025 | C23: 1 | D23: AMBA | E23: Sucursal Palermo | F23: Hogar | G23: 1646000
B24: 2025 | C24: 1 | D24: AMBA | E24: Sucursal Palermo | F24: Indumentaria | G24: 1227000
B25: 2025 | C25: 1 | D25: AMBA | E25: Sucursal Palermo | F25: Deportes | G25: 660000
B26: 2025 | C26: 1 | D26: AMBA | E26: Sucursal Avellaneda | F26: Tecnología | G26: 1894000
B27: 2025 | C27: 1 | D27: AMBA | E27: Sucursal Avellaneda | F27: Alimentos | G27: 1499000
B28: 2025 | C28: 1 | D28: AMBA | E28: Sucursal Avellaneda | F28: Hogar | G28: 1315000
B29: 2025 | C29: 1 | D29: AMBA | E29: Sucursal Avellaneda | F29: Indumentaria | G29: 998000
B30: 2025 | C30: 1 | D30: AMBA | E30: Sucursal Avellaneda | F30: Deportes | G30: 539000
B31: 2025 | C31: 1 | D31: Centro | E31: Sucursal Córdoba Centro | F31: Tecnología | G31: 1600000
B32: 2025 | C32: 1 | D32: Centro | E32: Sucursal Córdoba Centro | F32: Alimentos | G32: 1242000
... B1220: 2026 | C1220: 12 | D1220: Patagonia | E1220: Sucursal Bariloche | F1220: Deportes | G1220: 375000
